[2024-08-15T20:09:38.696+0000] {local_task_job_runner.py:120} INFO - ::group::Pre task execution logs
[2024-08-15T20:09:38.864+0000] {taskinstance.py:2076} INFO - Dependencies all met for dep_context=non-requeueable deps ti=<TaskInstance: csv_to_postgres.csv_to_stg manual__2024-08-15T20:09:30.782093+00:00 [queued]>
[2024-08-15T20:09:38.883+0000] {taskinstance.py:2076} INFO - Dependencies all met for dep_context=requeueable deps ti=<TaskInstance: csv_to_postgres.csv_to_stg manual__2024-08-15T20:09:30.782093+00:00 [queued]>
[2024-08-15T20:09:38.884+0000] {taskinstance.py:2306} INFO - Starting attempt 1 of 1
[2024-08-15T20:09:38.918+0000] {taskinstance.py:2330} INFO - Executing <Task(PythonOperator): csv_to_stg> on 2024-08-15 20:09:30.782093+00:00
[2024-08-15T20:09:38.938+0000] {warnings.py:112} WARNING - /home/***/.local/lib/python3.12/site-packages/***/task/task_runner/standard_task_runner.py:62: DeprecationWarning: This process (pid=1785) is multi-threaded, use of fork() may lead to deadlocks in the child.
  pid = os.fork()

[2024-08-15T20:09:38.944+0000] {standard_task_runner.py:64} INFO - Started process 1796 to run task
[2024-08-15T20:09:38.950+0000] {standard_task_runner.py:90} INFO - Running: ['***', 'tasks', 'run', 'csv_to_postgres', 'csv_to_stg', 'manual__2024-08-15T20:09:30.782093+00:00', '--job-id', '38', '--raw', '--subdir', 'DAGS_FOLDER/main.py', '--cfg-path', '/tmp/tmpj0xru_ir']
[2024-08-15T20:09:38.951+0000] {standard_task_runner.py:91} INFO - Job 38: Subtask csv_to_stg
[2024-08-15T20:09:39.196+0000] {task_command.py:426} INFO - Running <TaskInstance: csv_to_postgres.csv_to_stg manual__2024-08-15T20:09:30.782093+00:00 [running]> on host aa3ef9d15753
[2024-08-15T20:09:39.597+0000] {taskinstance.py:2648} INFO - Exporting env vars: AIRFLOW_CTX_DAG_OWNER='gena' AIRFLOW_CTX_DAG_ID='csv_to_postgres' AIRFLOW_CTX_TASK_ID='csv_to_stg' AIRFLOW_CTX_EXECUTION_DATE='2024-08-15T20:09:30.782093+00:00' AIRFLOW_CTX_TRY_NUMBER='1' AIRFLOW_CTX_DAG_RUN_ID='manual__2024-08-15T20:09:30.782093+00:00'
[2024-08-15T20:09:39.611+0000] {taskinstance.py:430} INFO - ::endgroup::
[2024-08-15T20:09:39.654+0000] {base.py:84} INFO - Using connection ID 'db' for task execution.
[2024-08-15T20:09:39.871+0000] {logging_mixin.py:188} INFO - Error occurred while loading data into платформы: (psycopg2.errors.UniqueViolation) duplicate key value violates unique constraint "платформы_pkey"
DETAIL:  Key (id)=(239034) already exists.

[SQL: INSERT INTO stg."платформы" ("название", "активность", "Сорт.", "Дата изм.", id) VALUES (%(название)s, %(активность)s, %(Сорт.)s, %(Дата_изм.)s, %(id)s)]
[parameters: ({'название': 'Arenadata', 'активность': 'Да', 'Сорт.': 500, 'Дата_изм.': '08.09.2022 17:34:33', 'id': 239034}, {'название': 'Informatica', 'активность': 'Да', 'Сорт.': 500, 'Дата_изм.': '08.09.2022 17:34:33', 'id': 239035}, {'название': 'Luxms BI', 'активность': 'Да', 'Сорт.': 500, 'Дата_изм.': '08.09.2022 17:34:33', 'id': 239036}, {'название': 'MS Azure', 'активность': 'Да', 'Сорт.': 500, 'Дата_изм.': '08.09.2022 17:34:33', 'id': 239037}, {'название': 'MS Power BI', 'активность': 'Да', 'Сорт.': 500, 'Дата_изм.': '08.09.2022 17:34:33', 'id': 239038}, {'название': 'MS SQL Server', 'активность': 'Да', 'Сорт.': 500, 'Дата_изм.': '08.09.2022 17:34:33', 'id': 239039}, {'название': 'MS SQL Server Master Data Services (MDS)', 'активность': 'Да', 'Сорт.': 500, 'Дата_изм.': '08.09.2022 17:34:33', 'id': 239040}, {'название': 'MS SQL Server Analysis Services (SSAS)', 'активность': 'Да', 'Сорт.': 500, 'Дата_изм.': '08.09.2022 17:34:33', 'id': 239041}  ... displaying 10 of 40 total bound parameter sets ...  {'название': 'Ibm Cognos/ Ibm Planning Analytics', 'активность': 'Да', 'Сорт.': 500, 'Дата_изм.': '21.10.2020 13:17:53', 'id': 115673}, {'название': 'Другое', 'активность': 'Да', 'Сорт.': 500, 'Дата_изм.': '21.10.2020 13:17:53', 'id': 115674})]
(Background on this error at: https://sqlalche.me/e/14/gkpj)
[2024-08-15T20:09:39.872+0000] {logging_mixin.py:188} INFO - Failed to process file /opt/***/source_data/платформы.csv.
[2024-08-15T20:09:39.874+0000] {logging_mixin.py:188} INFO - Error: 'Connection' object has no attribute 'rollback'
[2024-08-15T20:09:39.875+0000] {python.py:237} INFO - Done. Returned value was: None
[2024-08-15T20:09:39.879+0000] {taskinstance.py:441} INFO - ::group::Post task execution logs
[2024-08-15T20:09:39.898+0000] {taskinstance.py:1206} INFO - Marking task as SUCCESS. dag_id=csv_to_postgres, task_id=csv_to_stg, run_id=manual__2024-08-15T20:09:30.782093+00:00, execution_date=20240815T200930, start_date=20240815T200938, end_date=20240815T200939
[2024-08-15T20:09:39.948+0000] {local_task_job_runner.py:243} INFO - Task exited with return code 0
[2024-08-15T20:09:39.987+0000] {taskinstance.py:3503} INFO - 0 downstream tasks scheduled from follow-on schedule check
[2024-08-15T20:09:39.990+0000] {local_task_job_runner.py:222} INFO - ::endgroup::
